2025-03-24 17:08:52,144 ERROR: Exception on /api/auth/login [POST] [in /home/gachuuri/.local/lib/python3.10/site-packages/flask/app.py:875]
Traceback (most recent call last):
  File "/usr/local/lib/python3.10/dist-packages/sqlalchemy/engine/base.py", line 146, in __init__
    self._dbapi_connection = engine.raw_connection()
  File "/usr/local/lib/python3.10/dist-packages/sqlalchemy/engine/base.py", line 3302, in raw_connection
    return self.pool.connect()
  File "/usr/local/lib/python3.10/dist-packages/sqlalchemy/pool/base.py", line 449, in connect
    return _ConnectionFairy._checkout(self)
  File "/usr/local/lib/python3.10/dist-packages/sqlalchemy/pool/base.py", line 1263, in _checkout
    fairy = _ConnectionRecord.checkout(pool)
  File "/usr/local/lib/python3.10/dist-packages/sqlalchemy/pool/base.py", line 712, in checkout
    rec = pool._do_get()
  File "/usr/local/lib/python3.10/dist-packages/sqlalchemy/pool/impl.py", line 179, in _do_get
    with util.safe_reraise():
  File "/usr/local/lib/python3.10/dist-packages/sqlalchemy/util/langhelpers.py", line 146, in __exit__
    raise exc_value.with_traceback(exc_tb)
  File "/usr/local/lib/python3.10/dist-packages/sqlalchemy/pool/impl.py", line 177, in _do_get
    return self._create_connection()
  File "/usr/local/lib/python3.10/dist-packages/sqlalchemy/pool/base.py", line 390, in _create_connection
    return _ConnectionRecord(self)
  File "/usr/local/lib/python3.10/dist-packages/sqlalchemy/pool/base.py", line 674, in __init__
    self.__connect()
  File "/usr/local/lib/python3.10/dist-packages/sqlalchemy/pool/base.py", line 900, in __connect
    with util.safe_reraise():
  File "/usr/local/lib/python3.10/dist-packages/sqlalchemy/util/langhelpers.py", line 146, in __exit__
    raise exc_value.with_traceback(exc_tb)
  File "/usr/local/lib/python3.10/dist-packages/sqlalchemy/pool/base.py", line 896, in __connect
    self.dbapi_connection = connection = pool._invoke_creator(self)
  File "/usr/local/lib/python3.10/dist-packages/sqlalchemy/engine/create.py", line 643, in connect
    return dialect.connect(*cargs, **cparams)
  File "/usr/local/lib/python3.10/dist-packages/sqlalchemy/engine/default.py", line 621, in connect
    return self.loaded_dbapi.connect(*cargs, **cparams)
  File "/home/gachuuri/.local/lib/python3.10/site-packages/pymysql/connections.py", line 361, in __init__
    self.connect()
  File "/home/gachuuri/.local/lib/python3.10/site-packages/pymysql/connections.py", line 669, in connect
    self._request_authentication()
  File "/home/gachuuri/.local/lib/python3.10/site-packages/pymysql/connections.py", line 979, in _request_authentication
    auth_packet = _auth.caching_sha2_password_auth(self, auth_packet)
  File "/home/gachuuri/.local/lib/python3.10/site-packages/pymysql/_auth.py", line 268, in caching_sha2_password_auth
    pkt = _roundtrip(conn, data)
  File "/home/gachuuri/.local/lib/python3.10/site-packages/pymysql/_auth.py", line 121, in _roundtrip
    pkt = conn._read_packet()
  File "/home/gachuuri/.local/lib/python3.10/site-packages/pymysql/connections.py", line 775, in _read_packet
    packet.raise_for_error()
  File "/home/gachuuri/.local/lib/python3.10/site-packages/pymysql/protocol.py", line 219, in raise_for_error
    err.raise_mysql_exception(self._data)
  File "/home/gachuuri/.local/lib/python3.10/site-packages/pymysql/err.py", line 150, in raise_mysql_exception
    raise errorclass(errno, errval)
pymysql.err.OperationalError: (1045, "Access denied for user 'eco_admin'@'localhost' (using password: YES)")

The above exception was the direct cause of the following exception:

Traceback (most recent call last):
  File "/home/gachuuri/.local/lib/python3.10/site-packages/flask/app.py", line 1511, in wsgi_app
    response = self.full_dispatch_request()
  File "/home/gachuuri/.local/lib/python3.10/site-packages/flask/app.py", line 919, in full_dispatch_request
    rv = self.handle_user_exception(e)
  File "/home/gachuuri/.local/lib/python3.10/site-packages/flask_cors/extension.py", line 194, in wrapped_function
    return cors_after_request(app.make_response(f(*args, **kwargs)))
  File "/home/gachuuri/.local/lib/python3.10/site-packages/flask/app.py", line 917, in full_dispatch_request
    rv = self.dispatch_request()
  File "/home/gachuuri/.local/lib/python3.10/site-packages/flask/app.py", line 902, in dispatch_request
    return self.ensure_sync(self.view_functions[rule.endpoint])(**view_args)  # type: ignore[no-any-return]
  File "/home/gachuuri/Building/Eco-Connect/app/routes/auth.py", line 55, in login
    user = User.query.filter_by(username=username).first()
  File "/usr/local/lib/python3.10/dist-packages/sqlalchemy/orm/query.py", line 2728, in first
    return self.limit(1)._iter().first()  # type: ignore
  File "/usr/local/lib/python3.10/dist-packages/sqlalchemy/orm/query.py", line 2827, in _iter
    result: Union[ScalarResult[_T], Result[_T]] = self.session.execute(
  File "/usr/local/lib/python3.10/dist-packages/sqlalchemy/orm/session.py", line 2362, in execute
    return self._execute_internal(
  File "/usr/local/lib/python3.10/dist-packages/sqlalchemy/orm/session.py", line 2237, in _execute_internal
    conn = self._connection_for_bind(bind)
  File "/usr/local/lib/python3.10/dist-packages/sqlalchemy/orm/session.py", line 2106, in _connection_for_bind
    return trans._connection_for_bind(engine, execution_options)
  File "<string>", line 2, in _connection_for_bind
  File "/usr/local/lib/python3.10/dist-packages/sqlalchemy/orm/state_changes.py", line 139, in _go
    ret_value = fn(self, *arg, **kw)
  File "/usr/local/lib/python3.10/dist-packages/sqlalchemy/orm/session.py", line 1189, in _connection_for_bind
    conn = bind.connect()
  File "/usr/local/lib/python3.10/dist-packages/sqlalchemy/engine/base.py", line 3278, in connect
    return self._connection_cls(self)
  File "/usr/local/lib/python3.10/dist-packages/sqlalchemy/engine/base.py", line 148, in __init__
    Connection._handle_dbapi_exception_noconnection(
  File "/usr/local/lib/python3.10/dist-packages/sqlalchemy/engine/base.py", line 2442, in _handle_dbapi_exception_noconnection
    raise sqlalchemy_exception.with_traceback(exc_info[2]) from e
  File "/usr/local/lib/python3.10/dist-packages/sqlalchemy/engine/base.py", line 146, in __init__
    self._dbapi_connection = engine.raw_connection()
  File "/usr/local/lib/python3.10/dist-packages/sqlalchemy/engine/base.py", line 3302, in raw_connection
    return self.pool.connect()
  File "/usr/local/lib/python3.10/dist-packages/sqlalchemy/pool/base.py", line 449, in connect
    return _ConnectionFairy._checkout(self)
  File "/usr/local/lib/python3.10/dist-packages/sqlalchemy/pool/base.py", line 1263, in _checkout
    fairy = _ConnectionRecord.checkout(pool)
  File "/usr/local/lib/python3.10/dist-packages/sqlalchemy/pool/base.py", line 712, in checkout
    rec = pool._do_get()
  File "/usr/local/lib/python3.10/dist-packages/sqlalchemy/pool/impl.py", line 179, in _do_get
    with util.safe_reraise():
  File "/usr/local/lib/python3.10/dist-packages/sqlalchemy/util/langhelpers.py", line 146, in __exit__
    raise exc_value.with_traceback(exc_tb)
  File "/usr/local/lib/python3.10/dist-packages/sqlalchemy/pool/impl.py", line 177, in _do_get
    return self._create_connection()
  File "/usr/local/lib/python3.10/dist-packages/sqlalchemy/pool/base.py", line 390, in _create_connection
    return _ConnectionRecord(self)
  File "/usr/local/lib/python3.10/dist-packages/sqlalchemy/pool/base.py", line 674, in __init__
    self.__connect()
  File "/usr/local/lib/python3.10/dist-packages/sqlalchemy/pool/base.py", line 900, in __connect
    with util.safe_reraise():
  File "/usr/local/lib/python3.10/dist-packages/sqlalchemy/util/langhelpers.py", line 146, in __exit__
    raise exc_value.with_traceback(exc_tb)
  File "/usr/local/lib/python3.10/dist-packages/sqlalchemy/pool/base.py", line 896, in __connect
    self.dbapi_connection = connection = pool._invoke_creator(self)
  File "/usr/local/lib/python3.10/dist-packages/sqlalchemy/engine/create.py", line 643, in connect
    return dialect.connect(*cargs, **cparams)
  File "/usr/local/lib/python3.10/dist-packages/sqlalchemy/engine/default.py", line 621, in connect
    return self.loaded_dbapi.connect(*cargs, **cparams)
  File "/home/gachuuri/.local/lib/python3.10/site-packages/pymysql/connections.py", line 361, in __init__
    self.connect()
  File "/home/gachuuri/.local/lib/python3.10/site-packages/pymysql/connections.py", line 669, in connect
    self._request_authentication()
  File "/home/gachuuri/.local/lib/python3.10/site-packages/pymysql/connections.py", line 979, in _request_authentication
    auth_packet = _auth.caching_sha2_password_auth(self, auth_packet)
  File "/home/gachuuri/.local/lib/python3.10/site-packages/pymysql/_auth.py", line 268, in caching_sha2_password_auth
    pkt = _roundtrip(conn, data)
  File "/home/gachuuri/.local/lib/python3.10/site-packages/pymysql/_auth.py", line 121, in _roundtrip
    pkt = conn._read_packet()
  File "/home/gachuuri/.local/lib/python3.10/site-packages/pymysql/connections.py", line 775, in _read_packet
    packet.raise_for_error()
  File "/home/gachuuri/.local/lib/python3.10/site-packages/pymysql/protocol.py", line 219, in raise_for_error
    err.raise_mysql_exception(self._data)
  File "/home/gachuuri/.local/lib/python3.10/site-packages/pymysql/err.py", line 150, in raise_mysql_exception
    raise errorclass(errno, errval)
sqlalchemy.exc.OperationalError: (pymysql.err.OperationalError) (1045, "Access denied for user 'eco_admin'@'localhost' (using password: YES)")
(Background on this error at: https://sqlalche.me/e/20/e3q8)
2025-03-24 17:08:52,247 CRITICAL: 500 Internal Server Error at http://127.0.0.1:5000/api/auth/login - Error: 500 Internal Server Error: The server encountered an internal error and was unable to complete your request. Either the server is overloaded or there is an error in the application. [in /home/gachuuri/Building/Eco-Connect/app/__init__.py:93]
